Traceback (most recent call last):
  File "/Users/gabrielsanchez/opt/anaconda3/lib/python3.8/site-packages/jupyter_cache/executors/utils.py", line 58, in single_nb_execution
    executenb(
  File "/Users/gabrielsanchez/opt/anaconda3/lib/python3.8/site-packages/nbclient/client.py", line 1087, in execute
    return NotebookClient(nb=nb, resources=resources, km=km, **kwargs).execute()
  File "/Users/gabrielsanchez/opt/anaconda3/lib/python3.8/site-packages/nbclient/util.py", line 74, in wrapped
    return just_run(coro(*args, **kwargs))
  File "/Users/gabrielsanchez/opt/anaconda3/lib/python3.8/site-packages/nbclient/util.py", line 53, in just_run
    return loop.run_until_complete(coro)
  File "/Users/gabrielsanchez/opt/anaconda3/lib/python3.8/asyncio/base_events.py", line 616, in run_until_complete
    return future.result()
  File "/Users/gabrielsanchez/opt/anaconda3/lib/python3.8/site-packages/nbclient/client.py", line 540, in async_execute
    await self.async_execute_cell(
  File "/Users/gabrielsanchez/opt/anaconda3/lib/python3.8/site-packages/nbclient/client.py", line 832, in async_execute_cell
    self._check_raise_for_error(cell, exec_reply)
  File "/Users/gabrielsanchez/opt/anaconda3/lib/python3.8/site-packages/nbclient/client.py", line 740, in _check_raise_for_error
    raise CellExecutionError.from_cell_and_msg(cell, exec_reply['content'])
nbclient.exceptions.CellExecutionError: An error occurred while executing the following cell:
------------------
n_states = 4
for c in countries:
    for r in range(n_states):
        #Variance-covariance matrices and mean vectors
        if g[f'dfm_{c}'][g[f'dfm_{c}']['predicted']==r].empty == False:
            g[f'S_{c}_{r}'] = pd.DataFrame(np.cov(g[f'dfm_{c}'][g[f'dfm_{c}']['predicted']==r][vars].T),
                                            columns=vars,
                                            index=vars)

            g[f'Î¼_{c}_{r}'] = g[f'dfm_{c}'][g[f'dfm_{c}']['predicted']==r][vars].mean()

        else:
            g[f'S_{c}_{r}'] = pd.DataFrame(np.cov(g[f'dfm_{c}'][vars].T),
                                            columns=vars,
                                            index=vars)

            g[f'Î¼_{c}_{r}'] = g[f'dfm_{c}'][vars].mean()

        for t in range(len(g[f'dfm_{c}'])):
            if np.linalg.det(g[f'S_{c}_{r}']) != 0:
                g[f'áºŸ_{c}_{t}_{r}'] = (g[f'dfm_{c}'][vars].iloc[t]-g[f'Î¼_{c}_{r}']
                                )@np.linalg.inv(g[f'S_{c}_{r}']
                                )@(g[f'dfm_{c}'][vars].iloc[t]-g[f'Î¼_{c}_{r}'])

            else:
                g[f'áºŸ_{c}_{t}_{r}'] = (g[f'dfm_{c}'][vars].iloc[t]-g[f'Î¼_{c}_{r}']
                                )@np.linalg.inv(np.cov(g[f'dfm_{c}'][vars].T)
                                )@(g[f'dfm_{c}'][vars].iloc[t]-g[f'Î¼_{c}_{r}'])
------------------

[0;31m---------------------------------------------------------------------------[0m
[0;31mKeyError[0m                                  Traceback (most recent call last)
File [0;32m~/opt/anaconda3/lib/python3.8/site-packages/pandas/core/indexes/base.py:3621[0m, in [0;36mIndex.get_loc[0;34m(self, key, method, tolerance)[0m
[1;32m   3620[0m [38;5;28;01mtry[39;00m:
[0;32m-> 3621[0m     [38;5;28;01mreturn[39;00m [38;5;28;43mself[39;49m[38;5;241;43m.[39;49m[43m_engine[49m[38;5;241;43m.[39;49m[43mget_loc[49m[43m([49m[43mcasted_key[49m[43m)[49m
[1;32m   3622[0m [38;5;28;01mexcept[39;00m [38;5;167;01mKeyError[39;00m [38;5;28;01mas[39;00m err:

File [0;32m~/opt/anaconda3/lib/python3.8/site-packages/pandas/_libs/index.pyx:136[0m, in [0;36mpandas._libs.index.IndexEngine.get_loc[0;34m()[0m

File [0;32m~/opt/anaconda3/lib/python3.8/site-packages/pandas/_libs/index.pyx:163[0m, in [0;36mpandas._libs.index.IndexEngine.get_loc[0;34m()[0m

File [0;32mpandas/_libs/hashtable_class_helper.pxi:5198[0m, in [0;36mpandas._libs.hashtable.PyObjectHashTable.get_item[0;34m()[0m

File [0;32mpandas/_libs/hashtable_class_helper.pxi:5206[0m, in [0;36mpandas._libs.hashtable.PyObjectHashTable.get_item[0;34m()[0m

[0;31mKeyError[0m: 'predicted'

The above exception was the direct cause of the following exception:

[0;31mKeyError[0m                                  Traceback (most recent call last)
Input [0;32mIn [4][0m, in [0;36m<cell line: 2>[0;34m()[0m
[1;32m      2[0m [38;5;28;01mfor[39;00m c [38;5;129;01min[39;00m countries:
[1;32m      3[0m     [38;5;28;01mfor[39;00m r [38;5;129;01min[39;00m [38;5;28mrange[39m(n_states):
[1;32m      4[0m         [38;5;66;03m#Variance-covariance matrices and mean vectors[39;00m
[0;32m----> 5[0m         [38;5;28;01mif[39;00m g[[38;5;124mf[39m[38;5;124m'[39m[38;5;124mdfm_[39m[38;5;132;01m{[39;00mc[38;5;132;01m}[39;00m[38;5;124m'[39m][[43mg[49m[43m[[49m[38;5;124;43mf[39;49m[38;5;124;43m'[39;49m[38;5;124;43mdfm_[39;49m[38;5;132;43;01m{[39;49;00m[43mc[49m[38;5;132;43;01m}[39;49;00m[38;5;124;43m'[39;49m[43m][49m[43m[[49m[38;5;124;43m'[39;49m[38;5;124;43mpredicted[39;49m[38;5;124;43m'[39;49m[43m][49m[38;5;241m==[39mr][38;5;241m.[39mempty [38;5;241m==[39m [38;5;28;01mFalse[39;00m:
[1;32m      6[0m             g[[38;5;124mf[39m[38;5;124m'[39m[38;5;124mS_[39m[38;5;132;01m{[39;00mc[38;5;132;01m}[39;00m[38;5;124m_[39m[38;5;132;01m{[39;00mr[38;5;132;01m}[39;00m[38;5;124m'[39m] [38;5;241m=[39m pd[38;5;241m.[39mDataFrame(np[38;5;241m.[39mcov(g[[38;5;124mf[39m[38;5;124m'[39m[38;5;124mdfm_[39m[38;5;132;01m{[39;00mc[38;5;132;01m}[39;00m[38;5;124m'[39m][g[[38;5;124mf[39m[38;5;124m'[39m[38;5;124mdfm_[39m[38;5;132;01m{[39;00mc[38;5;132;01m}[39;00m[38;5;124m'[39m][[38;5;124m'[39m[38;5;124mpredicted[39m[38;5;124m'[39m][38;5;241m==[39mr][[38;5;28mvars[39m][38;5;241m.[39mT),
[1;32m      7[0m                                             columns[38;5;241m=[39m[38;5;28mvars[39m,
[1;32m      8[0m                                             index[38;5;241m=[39m[38;5;28mvars[39m)
[1;32m     10[0m             g[[38;5;124mf[39m[38;5;124m'[39m[38;5;124mÎ¼_[39m[38;5;132;01m{[39;00mc[38;5;132;01m}[39;00m[38;5;124m_[39m[38;5;132;01m{[39;00mr[38;5;132;01m}[39;00m[38;5;124m'[39m] [38;5;241m=[39m g[[38;5;124mf[39m[38;5;124m'[39m[38;5;124mdfm_[39m[38;5;132;01m{[39;00mc[38;5;132;01m}[39;00m[38;5;124m'[39m][g[[38;5;124mf[39m[38;5;124m'[39m[38;5;124mdfm_[39m[38;5;132;01m{[39;00mc[38;5;132;01m}[39;00m[38;5;124m'[39m][[38;5;124m'[39m[38;5;124mpredicted[39m[38;5;124m'[39m][38;5;241m==[39mr][[38;5;28mvars[39m][38;5;241m.[39mmean()

File [0;32m~/opt/anaconda3/lib/python3.8/site-packages/pandas/core/frame.py:3505[0m, in [0;36mDataFrame.__getitem__[0;34m(self, key)[0m
[1;32m   3503[0m [38;5;28;01mif[39;00m [38;5;28mself[39m[38;5;241m.[39mcolumns[38;5;241m.[39mnlevels [38;5;241m>[39m [38;5;241m1[39m:
[1;32m   3504[0m     [38;5;28;01mreturn[39;00m [38;5;28mself[39m[38;5;241m.[39m_getitem_multilevel(key)
[0;32m-> 3505[0m indexer [38;5;241m=[39m [38;5;28;43mself[39;49m[38;5;241;43m.[39;49m[43mcolumns[49m[38;5;241;43m.[39;49m[43mget_loc[49m[43m([49m[43mkey[49m[43m)[49m
[1;32m   3506[0m [38;5;28;01mif[39;00m is_integer(indexer):
[1;32m   3507[0m     indexer [38;5;241m=[39m [indexer]

File [0;32m~/opt/anaconda3/lib/python3.8/site-packages/pandas/core/indexes/base.py:3623[0m, in [0;36mIndex.get_loc[0;34m(self, key, method, tolerance)[0m
[1;32m   3621[0m     [38;5;28;01mreturn[39;00m [38;5;28mself[39m[38;5;241m.[39m_engine[38;5;241m.[39mget_loc(casted_key)
[1;32m   3622[0m [38;5;28;01mexcept[39;00m [38;5;167;01mKeyError[39;00m [38;5;28;01mas[39;00m err:
[0;32m-> 3623[0m     [38;5;28;01mraise[39;00m [38;5;167;01mKeyError[39;00m(key) [38;5;28;01mfrom[39;00m [38;5;21;01merr[39;00m
[1;32m   3624[0m [38;5;28;01mexcept[39;00m [38;5;167;01mTypeError[39;00m:
[1;32m   3625[0m     [38;5;66;03m# If we have a listlike key, _check_indexing_error will raise[39;00m
[1;32m   3626[0m     [38;5;66;03m#  InvalidIndexError. Otherwise we fall through and re-raise[39;00m
[1;32m   3627[0m     [38;5;66;03m#  the TypeError.[39;00m
[1;32m   3628[0m     [38;5;28mself[39m[38;5;241m.[39m_check_indexing_error(key)

[0;31mKeyError[0m: 'predicted'
KeyError: 'predicted'

